Workbook

Sheet JobGroupExecutions
A1: id | B1: jobGroupId | C1: businessDate | D1: startTime | E1: tagId
A2: jge_0001 | B2: JG_TEST | C2: 2026-01-01 | D2: 0.25 | E2: [TAG_YEAR_START_DATE,TAG_MONTH_START_DATE]
A3: jge_0002 | B3: JG_TEST | C3: 2026-01-02 | D3: 0.25 | E3: [TAG_WEEKDAY_END_DATE]
A4: jge_0003 | B4: JG_TEST | C4: 2026-01-03 | D4: 0.25 | E4: [TAG_WEEKEND_START_DATE]
A5: jge_0004 | B5: JG_MID | C5: 2026-01-01 | D5: 0.58333333 | E5: [TAG_YEAR_START_DATE,TAG_MONTH_START_DATE]
A6: jge_0005 | B6: JG_MID | C6: 2026-01-02 | D6: 0.58333333 | E6: [TAG_WEEKDAY_END_DATE]
A7: jge_0006 | B7: JG_MID | C7: 2026-01-03 | D7: 0.58333333 | E7: [TAG_WEEKEND_START_DATE]
A8: jge_0007 | B8: JG_EOD | C8: 2026-01-01 | D8: 0.875 | E8: [TAG_YEAR_START_DATE,TAG_MONTH_START_DATE]
A9: jge_0008 | B9: JG_EOD | C9: 2026-01-02 | D9: 0.875 | E9: [TAG_WEEKDAY_END_DATE]
A10: jge_0009 | B10: JG_EOD | C10: 2026-01-03 | D10: 0.875 | E10: [TAG_WEEKEND_START_DATE]

Sheet JobContextExecutions
A1: id | B1: jobContextId | C1: jobGroupExecId | D1: businessDate | E1: expectedStartTime | F1: startTime | G1: endTime | H1: durationMs | I1: volume | J1: status | K1: exitCode | L1: exitMessage | M1: retryCount
A2: jbex_0001 | B2: ctx_0028 | C2: jge_0001 | D2: 2026-01-01 | E2: =JobGroupExecutions!D2 -> 0.25 | F2: =IF(JobGroupExecutions!D2 > ResourceAvailabilityEvents!D2, JobGroupExecutions!D2, ResourceAvailabilityEvents!D2) -> 0.26388889 | G2: =F2 + RANDBETWEEN(5, 120) / 86400 -> 0.2649537 | H2: =(G2 - F2) * 86400000 -> 92000 | I2: =RANDBETWEEN(80000, 120000) -> 89906 | J2: COMPLETED | K2: 0 | L2: Success | M2: 0
A3: jbex_0002 | B3: ctx_0022 | C3: jge_0001 | D3: 2026-01-01 | E3: =F3 -> 0.2649537 | F3: =G2 -> 0.2649537 | G3: =F3 + RANDBETWEEN(5, 120) / 86400 -> 0.26621528 | H3: =(G3 - F3) * 86400000 -> 109000 | I3: =RANDBETWEEN(80000, 120000) -> 81739 | J3: COMPLETED | K3: 0 | L3: Success | M3: 0
A4: jbex_0003 | B4: ctx_0023 | C4: jge_0001 | D4: 2026-01-01 | E4: =F4 -> 0.2649537 | F4: =G2 -> 0.2649537 | G4: =F4 + RANDBETWEEN(5, 120) / 86400 -> 0.26582176 | H4: =(G4 - F4) * 86400000 -> 75000 | I4: =RANDBETWEEN(80000, 120000) -> 93340 | J4: COMPLETED | K4: 0 | L4: Success | M4: 0
A5: jbex_0004 | B5: ctx_0024 | C5: jge_0001 | D5: 2026-01-01 | E5: =F5 -> 0.26621528 | F5: =G3 -> 0.26621528 | G5: =F5 + RANDBETWEEN(5, 120) / 86400 -> 0.26689815 | H5: =(G5 - F5) * 86400000 -> 59000 | I5: =RANDBETWEEN(80000, 120000) -> 95855 | J5: COMPLETED | K5: 0 | L5: Success | M5: 0
A6: jbex_0005 | B6: ctx_0025 | C6: jge_0001 | D6: 2026-01-01 | E6: =F6 -> 0.26582176 | F6: =G4 -> 0.26582176 | G6: =F6 + RANDBETWEEN(5, 120) / 86400 -> 0.26635417 | H6: =(G6 - F6) * 86400000 -> 46000 | I6: =RANDBETWEEN(80000, 120000) -> 82804 | J6: COMPLETED | K6: 0 | L6: Success | M6: 0
A7: jbex_0006 | B7: ctx_0026 | C7: jge_0001 | D7: 2026-01-01 | E7: =F7 -> 0.26689815 | F7: =IF(G5 > G6, G5, G6) -> 0.26689815 | G7: =F7 + RANDBETWEEN(5, 120) / 86400 -> 0.26706019 | H7: =(G7 - F7) * 86400000 -> 14000 | I7: =RANDBETWEEN(80000, 120000) -> 102375 | J7: COMPLETED | K7: 0 | L7: Success | M7: 0
A8: jbex_0007 | B8: ctx_0028 | C8: jge_0002 | D8: 2026-01-02 | E8: =JobGroupExecutions!D3 -> 0.25 | F8: =IF(JobGroupExecutions!D3 > ResourceAvailabilityEvents!D3, JobGroupExecutions!D3, ResourceAvailabilityEvents!D3) -> 0.25 | G8: =F8 + RANDBETWEEN(5, 120) / 86400 -> 0.25056713 | H8: =(G8 - F8) * 86400000 -> 49000 | I8: =RANDBETWEEN(20000, 40000) -> 28069 | J8: COMPLETED | K8: 0 | L8: Success | M8: 0
A9: jbex_0008 | B9: ctx_0022 | C9: jge_0002 | D9: 2026-01-02 | E9: =F9 -> 0.25056713 | F9: =G8 -> 0.25056713 | G9: =F9 + RANDBETWEEN(5, 120) / 86400 -> 0.25072917 | H9: =(G9 - F9) * 86400000 -> 14000 | I9: =RANDBETWEEN(20000, 40000) -> 26429 | J9: COMPLETED | K9: 0 | L9: Success | M9: 0
A10: jbex_0009 | B10: ctx_0023 | C10: jge_0002 | D10: 2026-01-02 | E10: =F10 -> 0.25056713 | F10: =G8 -> 0.25056713 | G10: =F10 + RANDBETWEEN(5, 120) / 86400 -> 0.25186343 | H10: =(G10 - F10) * 86400000 -> 112000 | I10: =RANDBETWEEN(20000, 40000) -> 22846 | J10: COMPLETED | K10: 0 | L10: Success | M10: 0
A11: jbex_0010 | B11: ctx_0024 | C11: jge_0002 | D11: 2026-01-02 | E11: =F11 -> 0.25072917 | F11: =G9 -> 0.25072917 | G11: =F11 + RANDBETWEEN(5, 120) / 86400 -> 0.25091435 | H11: =(G11 - F11) * 86400000 -> 16000 | I11: =RANDBETWEEN(20000, 40000) -> 37015 | J11: COMPLETED | K11: 0 | L11: Success | M11: 0
A12: jbex_0011 | B12: ctx_0025 | C12: jge_0002 | D12: 2026-01-02 | E12: =F12 -> 0.25186343 | F12: =G10 -> 0.25186343 | G12: =F12 + RANDBETWEEN(5, 120) / 86400 -> 0.25315972 | H12: =(G12 - F12) * 86400000 -> 112000 | I12: =RANDBETWEEN(20000, 40000) -> 27002 | J12: COMPLETED | K12: 0 | L12: Success | M12: 0
A13: jbex_0012 | B13: ctx_0026 | C13: jge_0002 | D13: 2026-01-02 | E13: =F13 -> 0.25315972 | F13: =IF(G11 > G12, G11, G12) -> 0.25315972 | G13: =F13 + RANDBETWEEN(5, 120) / 86400 -> 0.2537037 | H13: =(G13 - F13) * 86400000 -> 47000 | I13: =RANDBETWEEN(20000, 40000) -> 24396 | J13: COMPLETED | K13: 0 | L13: Success | M13: 0
A14: jbex_0013 | B14: ctx_0028 | C14: jge_0003 | D14: 2026-01-03 | E14: =JobGroupExecutions!D4 -> 0.25 | F14: =IF(JobGroupExecutions!D4 > ResourceAvailabilityEvents!D4, JobGroupExecutions!D4, ResourceAvailabilityEvents!D4) -> 0.25 | G14: =F14 + RANDBETWEEN(5, 120) / 86400 -> 0.25136574 | H14: =(G14 - F14) * 86400000 -> 118000 | I14: =RANDBETWEEN(20000, 40000) -> 31464 | J14: COMPLETED | K14: 0 | L14: Success | M14: 0
A15: jbex_0014 | B15: ctx_0022 | C15: jge_0003 | D15: 2026-01-03 | E15: =F15 -> 0.25136574 | F15: =G14 -> 0.25136574 | G15: =F15 + RANDBETWEEN(5, 120) / 86400 -> 0.25149306 | H15: =(G15 - F15) * 86400000 -> 11000 | I15: =RANDBETWEEN(20000, 40000) -> 25244 | J15: COMPLETED | K15: 0 | L15: Success | M15: 0
A16: jbex_0015 | B16: ctx_0023 | C16: jge_0003 | D16: 2026-01-03 | E16: =F16 -> 0.25136574 | F16: =G14 -> 0.25136574 | G16: =F16 + RANDBETWEEN(5, 120) / 86400 -> 0.25184028 | H16: =(G16 - F16) * 86400000 -> 41000 | I16: =RANDBETWEEN(20000, 40000) -> 21908 | J16: COMPLETED | K16: 0 | L16: Success | M16: 0
A17: jbex_0016 | B17: ctx_0024 | C17: jge_0003 | D17: 2026-01-03 | E17: =F17 -> 0.25149306 | F17: =G15 -> 0.25149306 | G17: =F17 + RANDBETWEEN(5, 120) / 86400 -> 0.25197917 | H17: =(G17 - F17) * 86400000 -> 42000 | I17: =RANDBETWEEN(20000, 40000) -> 30353 | J17: COMPLETED | K17: 0 | L17: Success | M17: 0
A18: jbex_0017 | B18: ctx_0025 | C18: jge_0003 | D18: 2026-01-03 | E18: =F18 -> 0.25184028 | F18: =G16 -> 0.25184028 | G18: =F18 + RANDBETWEEN(5, 120) / 86400 -> 0.25270833 | H18: =(G18 - F18) * 86400000 -> 75000 | I18: =RANDBETWEEN(20000, 40000) -> 21463 | J18: COMPLETED | K18: 0 | L18: Success | M18: 0
A19: jbex_0018 | B19: ctx_0026 | C19: jge_0003 | D19: 2026-01-03 | E19: =F19 -> 0.25270833 | F19: =IF(G17 > G18, G17, G18) -> 0.25270833 | G19: =F19 + RANDBETWEEN(5, 120) / 86400 -> 0.25408565 | H19: =(G19 - F19) * 86400000 -> 119000 | I19: =RANDBETWEEN(20000, 40000) -> 27814 | J19: COMPLETED | K19: 0 | L19: Success | M19: 0
A20: jbex_0019 | B20: ctx_0019 | C20: jge_0004 | D20: 2026-01-01 | E20: =JobGroupExecutions!D5 -> 0.58333333 | F20: =IF(JobGroupExecutions!D5 > ResourceAvailabilityEvents!D11, JobGroupExecutions!D5, ResourceAvailabilityEvents!D11) -> 0.58333333 | G20: =F20 + RANDBETWEEN(280, 400) / 86400 -> 0.58674769 | H20: =(G20 - F20) * 86400000 -> 295000 | I20: =RANDBETWEEN(90000, 120000) -> 117884 | J20: COMPLETED | K20: 0 | L20: Success | M20: 0
A21: jbex_0020 | B21: ctx_0013 | C21: jge_0004 | D21: 2026-01-01 | E21: =F21 -> 0.58674769 | F21: =G20 -> 0.58674769 | G21: =F21 + RANDBETWEEN(280, 390) / 86400 -> 0.59094907 | H21: =(G21 - F21) * 86400000 -> 363000 | I21: =RANDBETWEEN(90000, 120000) -> 96350 | J21: COMPLETED | K21: 0 | L21: Success | M21: 0
A22: jbex_0021 | B22: ctx_0014 | C22: jge_0004 | D22: 2026-01-01 | E22: =F22 -> 0.58674769 | F22: =G20 -> 0.58674769 | G22: =F22 + RANDBETWEEN(350, 450) / 86400 -> 0.59158565 | H22: =(G22 - F22) * 86400000 -> 418000 | I22: =RANDBETWEEN(90000, 120000) -> 115907 | J22: COMPLETED | K22: 0 | L22: Success | M22: 0
A23: jbex_0022 | B23: ctx_0015 | C23: jge_0004 | D23: 2026-01-01 | E23: =F23 -> 0.59094907 | F23: =G21 -> 0.59094907 | G23: =F23 + RANDBETWEEN(410, 710) / 86400 -> 0.59577546 | H23: =(G23 - F23) * 86400000 -> 417000 | I23: =RANDBETWEEN(90000, 120000) -> 95009 | J23: COMPLETED | K23: 0 | L23: Success | M23: 0
A24: jbex_0023 | B24: ctx_0016 | C24: jge_0004 | D24: 2026-01-01 | E24: =F24 -> 0.59158565 | F24: =G22 -> 0.59158565 | G24: =F24 + RANDBETWEEN(350, 650) / 86400 -> 0.59766204 | H24: =(G24 - F24) * 86400000 -> 525000 | I24: =RANDBETWEEN(90000, 120000) -> 115421 | J24: COMPLETED | K24: 0 | L24: Success | M24: 0
A25: jbex_0024 | B25: ctx_0018 | C25: jge_0004 | D25: 2026-01-01 | E25: =F25 -> 0.59577546 | F25: =G23 -> 0.59577546 | G25: =F25 + RANDBETWEEN(250, 450) / 86400 -> 0.599375 | H25: =(G25 - F25) * 86400000 -> 311000 | I25: =RANDBETWEEN(90000, 120000) -> 91940 | J25: COMPLETED | K25: 0 | L25: Success | M25: 0
A26: jbex_0025 | B26: ctx_0017 | C26: jge_0004 | D26: 2026-01-01 | E26: =F26 -> 0.59766204 | F26: =G24 -> 0.59766204 | G26: =F26 + RANDBETWEEN(250, 450) / 86400 -> 0.60142361 | H26: =(G26 - F26) * 86400000 -> 325000 | I26: =RANDBETWEEN(90000, 120000) -> 100051 | J26: COMPLETED | K26: 0 | L26: Success | M26: 0
A27: jbex_0026 | B27: ctx_0020 | C27: jge_0004 | D27: 2026-01-01 | E27: =F27 -> 0.60142361 | F27: =G26 -> 0.60142361 | G27: =F27 + RANDBETWEEN(250, 450) / 86400 -> 0.60663194 | H27: =(G27 - F27) * 86400000 -> 450000 | I27: =RANDBETWEEN(90000, 120000) -> 99442 | J27: COMPLETED | K27: 0 | L27: Success | M27: 0
A28: jbex_0027 | B28: ctx_0012 | C28: jge_0004 | D28: 2026-01-01 | E28: =F28 -> 0.60663194 | F28: =IF(G25 > G27, G25, G27) -> 0.60663194 | G28: =F28 + RANDBETWEEN(150, 350) / 86400 -> 0.60993056 | H28: =(G28 - F28) * 86400000 -> 285000 | I28: =RANDBETWEEN(90000, 120000) -> 97176 | J28: COMPLETED | K28: 0 | L28: Success | M28: 0
A29: jbex_0028 | B29: ctx_0019 | C29: jge_0005 | D29: 2026-01-02 | E29: =JobGroupExecutions!D6 -> 0.58333333 | F29: =IF(JobGroupExecutions!D6 > ResourceAvailabilityEvents!D12, JobGroupExecutions!D6, ResourceAvailabilityEvents!D12) -> 0.58333333 | G29: =F29 + RANDBETWEEN(280, 400) / 86400 -> 0.58664352 | H29: =(G29 - F29) * 86400000 -> 286000 | I29: =RANDBETWEEN(20000, 30000) -> 23886 | J29: COMPLETED | K29: 0 | L29: Success | M29: 0
A30: jbex_0029 | B30: ctx_0013 | C30: jge_0005 | D30: 2026-01-02 | E30: =F30 -> 0.58664352 | F30: =G29 -> 0.58664352 | G30: =F30 + RANDBETWEEN(280, 390) / 86400 -> 0.59074074 | H30: =(G30 - F30) * 86400000 -> 354000 | I30: =RANDBETWEEN(20000, 30000) -> 23913 | J30: COMPLETED | K30: 0 | L30: Success | M30: 0
A31: jbex_0030 | B31: ctx_0014 | C31: jge_0005 | D31: 2026-01-02 | E31: =F31 -> 0.58664352 | F31: =G29 -> 0.58664352 | G31: =F31 + RANDBETWEEN(350, 450) / 86400 -> 0.59113426 | H31: =(G31 - F31) * 86400000 -> 388000 | I31: =RANDBETWEEN(20000, 30000) -> 22230 | J31: COMPLETED | K31: 0 | L31: Success | M31: 0
A32: jbex_0031 | B32: ctx_0015 | C32: jge_0005 | D32: 2026-01-02 | E32: =F32 -> 0.59074074 | F32: =G30 -> 0.59074074 | G32: =F32 + RANDBETWEEN(410, 710) / 86400 -> 0.59703704 | H32: =(G32 - F32) * 86400000 -> 544000 | I32: =RANDBETWEEN(20000, 30000) -> 22839 | J32: COMPLETED | K32: 0 | L32: Success | M32: 0
A33: jbex_0032 | B33: ctx_0016 | C33: jge_0005 | D33: 2026-01-02 | E33: =F33 -> 0.59113426 | F33: =G31 -> 0.59113426 | G33: =F33 + RANDBETWEEN(350, 650) / 86400 -> 0.59733796 | H33: =(G33 - F33) * 86400000 -> 536000 | I33: =RANDBETWEEN(20000, 30000) -> 28149 | J33: COMPLETED | K33: 0 | L33: Success | M33: 0
A34: jbex_0033 | B34: ctx_0018 | C34: jge_0005 | D34: 2026-01-02 | E34: =F34 -> 0.59703704 | F34: =G32 -> 0.59703704 | G34: =F34 + RANDBETWEEN(250, 450) / 86400 -> 0.60206019 | H34: =(G34 - F34) * 86400000 -> 434000 | I34: =RANDBETWEEN(20000, 30000) -> 27405 | J34: COMPLETED | K34: 0 | L34: Success | M34: 0
A35: jbex_0034 | B35: ctx_0017 | C35: jge_0005 | D35: 2026-01-02 | E35: =F35 -> 0.59733796 | F35: =G33 -> 0.59733796 | G35: =F35 + RANDBETWEEN(250, 450) / 86400 -> 0.6012037 | H35: =(G35 - F35) * 86400000 -> 334000 | I35: =RANDBETWEEN(20000, 30000) -> 21010 | J35: COMPLETED | K35: 0 | L35: Success | M35: 0
A36: jbex_0035 | B36: ctx_0020 | C36: jge_0005 | D36: 2026-01-02 | E36: =F36 -> 0.6012037 | F36: =G35 -> 0.6012037 | G36: =F36 + RANDBETWEEN(250, 450) / 86400 -> 0.6052662 | H36: =(G36 - F36) * 86400000 -> 351000 | I36: =RANDBETWEEN(20000, 30000) -> 21184 | J36: COMPLETED | K36: 0 | L36: Success | M36: 0
A37: jbex_0036 | B37: ctx_0012 | C37: jge_0005 | D37: 2026-01-02 | E37: =F37 -> 0.6052662 | F37: =IF(G34 > G36, G34, G36) -> 0.6052662 | G37: =F37 + RANDBETWEEN(150, 350) / 86400 -> 0.60929398 | H37: =(G37 - F37) * 86400000 -> 348000 | I37: =RANDBETWEEN(20000, 30000) -> 25302 | J37: COMPLETED | K37: 0 | L37: Success | M37: 0
A38: jbex_0037 | B38: ctx_0019 | C38: jge_0006 | D38: 2026-01-03 | E38: =JobGroupExecutions!D7 -> 0.58333333 | F38: =IF(JobGroupExecutions!D7 > ResourceAvailabilityEvents!D13, JobGroupExecutions!D7, ResourceAvailabilityEvents!D13) -> 0.58333333 | G38: =F38 + RANDBETWEEN(280, 400) / 86400 -> 0.58744213 | H38: =(G38 - F38) * 86400000 -> 355000 | I38: =RANDBETWEEN(30000, 40000) -> 36517 | J38: COMPLETED | K38: 0 | L38: Success | M38: 0
A39: jbex_0038 | B39: ctx_0013 | C39: jge_0006 | D39: 2026-01-03 | E39: =F39 -> 0.58744213 | F39: =G38 -> 0.58744213 | G39: =F39 + RANDBETWEEN(280, 390) / 86400 -> 0.59084491 | H39: =(G39 - F39) * 86400000 -> 294000 | I39: =RANDBETWEEN(30000, 40000) -> 34313 | J39: COMPLETED | K39: 0 | L39: Success | M39: 0
A40: jbex_0039 | B40: ctx_0014 | C40: jge_0006 | D40: 2026-01-03 | E40: =F40 -> 0.58744213 | F40: =G38 -> 0.58744213 | G40: =F40 + RANDBETWEEN(350, 450) / 86400 -> 0.59248843 | H40: =(G40 - F40) * 86400000 -> 436000 | I40: =RANDBETWEEN(30000, 40000) -> 36661 | J40: COMPLETED | K40: 0 | L40: Success | M40: 0
...

Sheet ResourceAvailabilityEvents
A1: id | B1: resourceId | C1: businessDate | D1: availabilityTime | E1: sizemb | F1: checksum | G1: detectedBy
A2: RSD_file1_20260101 | B2: RES_005 | C2: 2026-01-01 | D2: =(JobGroupExecutions!D2) + TIME(0,20,0) -> 0.26388889 | E2: =(JobContextExecutions!I2) / 1000 -> 89.906 | F2: {=_xlfn.TEXTJOIN("",,CHAR(RANDBETWEEN(65,90+IF(_xlfn.RANDARRAY(24)<0.5,32,0))))} -> ]SDOuPQuQNCENIKrH_DARUJY | G2: FILE_WATCHER
A3: RSD_file1_20250102 | B3: RES_005 | C3: 2026-01-02 | D3: =(JobGroupExecutions!D3) -> 0.25 | E3: =(JobContextExecutions!I8) / 1000 -> 28.069 | F3: {=_xlfn.TEXTJOIN("",,CHAR(RANDBETWEEN(65,90+IF(_xlfn.RANDARRAY(24)<0.5,32,0))))} -> JG]KVUuOUQJxPtF]XDQSCkDm | G3: FILE_WATCHER
A4: RSD_file1_20250103 | B4: RES_005 | C4: 2026-01-03 | D4: =(JobGroupExecutions!D4) -> 0.25 | E4: =(JobContextExecutions!I14) / 1000 -> 31.464 | F4: {=_xlfn.TEXTJOIN("",,CHAR(RANDBETWEEN(65,90+IF(_xlfn.RANDARRAY(24)<0.5,32,0))))} -> CjWWZSMVUbD^PxMGRAUONUBU | G4: FILE_WATCHER
A5: RSD_file2_20250101 | B5: RES_002 | C5: 2026-01-01 | D5: =(JobGroupExecutions!D8) -> 0.875 | E5: =(JobContextExecutions!I47) / 1000 -> 117.277 | F5: {=_xlfn.TEXTJOIN("",,CHAR(RANDBETWEEN(65,90+IF(_xlfn.RANDARRAY(24)<0.5,32,0))))} -> AOYraGbUURETlHkGHZcvR]NN | G5: FILE_WATCHER
A6: RSD_file2_20250102 | B6: RES_002 | C6: 2026-01-02 | D6: =(JobGroupExecutions!D9) -> 0.875 | E6: =(JobContextExecutions!I56) / 1000 -> 21.896 | F6: {=_xlfn.TEXTJOIN("",,CHAR(RANDBETWEEN(65,90+IF(_xlfn.RANDARRAY(24)<0.5,32,0))))} -> NWNfSRRSUMoVEtCgEUoP^LOG | G6: FILE_WATCHER
A7: RSD_file2_20250103 | B7: RES_002 | C7: 2026-01-03 | D7: =(JobGroupExecutions!D10) -> 0.875 | E7: =(JobContextExecutions!I65) / 1000 -> 27.233 | F7: {=_xlfn.TEXTJOIN("",,CHAR(RANDBETWEEN(65,90+IF(_xlfn.RANDARRAY(24)<0.5,32,0))))} -> PICmL^GOgHPKFJdMqnjrhUXV | G7: FILE_WATCHER
A8: RSD_file3_20260101 | B8: RES_004 | C8: 2026-01-01 | D8: =(JobGroupExecutions!D8) -> 0.875 | E8: =(JobContextExecutions!I47) / 1000 -> 117.277 | F8: {=_xlfn.TEXTJOIN("",,CHAR(RANDBETWEEN(65,90+IF(_xlfn.RANDARRAY(24)<0.5,32,0))))} -> WGWaBMQzJ\T^lMZKnZTBQWIU | G8: FILE_WATCHER
A9: RSD_file3_20260102 | B9: RES_004 | C9: 2026-01-02 | D9: =(JobGroupExecutions!D9) -> 0.875 | E9: =(JobContextExecutions!I56) / 1000 -> 21.896 | F9: {=_xlfn.TEXTJOIN("",,CHAR(RANDBETWEEN(65,90+IF(_xlfn.RANDARRAY(24)<0.5,32,0))))} -> IQESOD]FBvzNOEsUGYZSNZhU | G9: FILE_WATCHER
A10: RSD_file3_20260103 | B10: RES_004 | C10: 2026-01-03 | D10: =(JobGroupExecutions!D10) -> 0.875 | E10: =(JobContextExecutions!I65) / 1000 -> 27.233 | F10: {=_xlfn.TEXTJOIN("",,CHAR(RANDBETWEEN(65,90+IF(_xlfn.RANDARRAY(24)<0.5,32,0))))} -> VFUZVRQ^Hy]PxxEPDGtKSVKo | G10: FILE_WATCHER
A11: RSD_file4_20260101 | B11: RES_006 | C11: 2026-01-01 | D11: =(JobGroupExecutions!D5) -> 0.58333333 | E11: =(JobContextExecutions!I20) / 1000 -> 117.884 | F11: {=_xlfn.TEXTJOIN("",,CHAR(RANDBETWEEN(65,90+IF(_xlfn.RANDARRAY(24)<0.5,32,0))))} -> VXzKLWXHAUU_iEMZRBHlVChI | G11: FILE_WATCHER
A12: RSD_file4_20260102 | B12: RES_006 | C12: 2026-01-02 | D12: =(JobGroupExecutions!D6) -> 0.58333333 | E12: =(JobContextExecutions!I29) / 1000 -> 23.886 | F12: {=_xlfn.TEXTJOIN("",,CHAR(RANDBETWEEN(65,90+IF(_xlfn.RANDARRAY(24)<0.5,32,0))))} -> BXSVUYjLZVWEVKJHCvULQqbO | G12: FILE_WATCHER
A13: RSD_file4_20260103 | B13: RES_006 | C13: 2026-01-03 | D13: =(JobGroupExecutions!D7) -> 0.58333333 | E13: =(JobContextExecutions!I38) / 1000 -> 36.517 | F13: {=_xlfn.TEXTJOIN("",,CHAR(RANDBETWEEN(65,90+IF(_xlfn.RANDARRAY(24)<0.5,32,0))))} -> aGXInVLNRQJJC`jpCwCFFYSZ | G13: FILE_WATCHER
A14: RSD_file5_20260101 | B14: RES_001 | C14: 2026-01-01 | D14: =(JobGroupExecutions!D8) -> 0.875 | E14: =(JobContextExecutions!I47) / 1000 -> 117.277 | F14: {=_xlfn.TEXTJOIN("",,CHAR(RANDBETWEEN(65,90+IF(_xlfn.RANDARRAY(24)<0.5,32,0))))} -> JJAIohemU^pBXTFfJPEXBX]i | G14: FILE_WATCHER
A15: RSD_file5_20260102 | B15: RES_001 | C15: 2026-01-02 | D15: =(JobGroupExecutions!D9) -> 0.875 | E15: =(JobContextExecutions!I56) / 1000 -> 21.896 | F15: {=_xlfn.TEXTJOIN("",,CHAR(RANDBETWEEN(65,90+IF(_xlfn.RANDARRAY(24)<0.5,32,0))))} -> QKpRLgOpFvBSW]BVBsSoYK]m | G15: FILE_WATCHER
A16: RSD_file5_20260103 | B16: RES_001 | C16: 2026-01-03 | D16: =(JobGroupExecutions!D10) -> 0.875 | E16: =(JobContextExecutions!I65) / 1000 -> 27.233 | F16: {=_xlfn.TEXTJOIN("",,CHAR(RANDBETWEEN(65,90+IF(_xlfn.RANDARRAY(24)<0.5,32,0))))} -> TJFGHmBZECCZCQRHBGSWDOCC | G16: FILE_WATCHER
A17: RSD_file6_20260101 | B17: RES_003 | C17: 2026-01-01 | D17: =(JobGroupExecutions!D8) + TIME(0,35,0) -> 0.89930556 | E17: =(JobContextExecutions!I50) / 1000 -> 115.953 | F17: {=_xlfn.TEXTJOIN("",,CHAR(RANDBETWEEN(65,90+IF(_xlfn.RANDARRAY(24)<0.5,32,0))))} -> viVkQo\VphQHCeAHupVJFCUC | G17: FILE_WATCHER
A18: RSD_file6_20260102 | B18: RES_003 | C18: 2026-01-02 | D18: =(JobGroupExecutions!D9) -> 0.875 | E18: =(JobContextExecutions!I59) / 1000 -> 22.231 | F18: {=_xlfn.TEXTJOIN("",,CHAR(RANDBETWEEN(65,90+IF(_xlfn.RANDARRAY(24)<0.5,32,0))))} -> JZIXVQSFEWCF]NUjYKMVPVEF | G18: FILE_WATCHER
A19: RSD_file6_20260103 | B19: RES_003 | C19: 2026-01-03 | D19: =(JobGroupExecutions!D10) + TIME(1,5,0) -> 0.92013889 | E19: =(JobContextExecutions!I68) / 1000 -> 26.08 | F19: {=_xlfn.TEXTJOIN("",,CHAR(RANDBETWEEN(65,90+IF(_xlfn.RANDARRAY(24)<0.5,32,0))))} -> JMJFCHPFuFFJMBTIiIb`BKiv | G19: FILE_WATCHER
