Workbook

Sheet JobGroupExecutionsOLD
A1: jobGroupId | B1: businessDate | C1: startTime
A2: JG_TEST | B2: 2026-01-01 | C2: 0.25
A3: JG_TEST | B3: 2026-01-02 | C3: 0.25
A4: JG_TEST | B4: 2026-01-03 | C4: 0.25
A5: JG_MID | B5: 2026-01-01 | C5: 0.58333333
A6: JG_MID | B6: 2026-01-02 | C6: 0.58333333
A7: JG_MID | B7: 2026-01-03 | C7: 0.58333333
A8: JG_EOD | B8: 2026-01-01 | C8: 0.875
A9: JG_EOD | B9: 2026-01-02 | C9: 0.875
A10: JG_EOD | B10: 2026-01-03 | C10: 0.875

Sheet JobContextExecutions
A1: id | B1: jobContextId | C1: JobName | D1: businessDate | E1: expectedStartTime | F1: startTime | G1: endTime | H1: duration | I1: status | J1: exitCode | K1: exitMessage
A2: jbex_0001 | B2: ctx_0028 | C2: =_xlfn.XLOOKUP(B2, Mapping!A:A, Mapping!B:B, "Not Found") -> NEW-BB-FUNDING-RATES-DOWNLOAD | D2: 2026-01-01 | E2: =D2 + JobGroupExecutionsOLD!C2 -> 46023.25 | F2: =IF(E2 > ResourceAvailabilityEvents!E2, E2, ResourceAvailabilityEvents!E2) -> 46023.264 | G2: =F2 + RANDBETWEEN(5, 120) / 86400 -> 46023.264 | H2: =INT((G2 - F2) * 86400/60) + MOD(INT((G2 - F2) * 86400),60)/100 -> 0.52 | I2: COMPLETED | J2: 0 | K2: Success
A3: jbex_0002 | B3: ctx_0022 | C3: =_xlfn.XLOOKUP(B3, Mapping!A:A, Mapping!B:B, "Not Found") -> AR-ML-LS2-TRIGGER | D3: 2026-01-01 | E3: =F3 -> 46023.264 | F3: =G2 -> 46023.264 | G3: =F3 + RANDBETWEEN(5, 120) / 86400 -> 46023.265 | H3: =INT((G3 - F3) * 86400/60) + MOD(INT((G3 - F3) * 86400),60)/100 -> 1.14 | I3: COMPLETED | J3: 0 | K3: Success
A4: jbex_0003 | B4: ctx_0023 | C4: =_xlfn.XLOOKUP(B4, Mapping!A:A, Mapping!B:B, "Not Found") -> CODE-DESC | D4: 2026-01-01 | E4: =F4 -> 46023.264 | F4: =G2 -> 46023.264 | G4: =F4 + RANDBETWEEN(5, 120) / 86400 -> 46023.265 | H4: =INT((G4 - F4) * 86400/60) + MOD(INT((G4 - F4) * 86400),60)/100 -> 0.27 | I4: COMPLETED | J4: 0 | K4: Success
A5: jbex_0004 | B5: ctx_0024 | C5: =_xlfn.XLOOKUP(B5, Mapping!A:A, Mapping!B:B, "Not Found") -> ONLINE-TO-HIST-SYNC-EXCEPTIONS | D5: 2026-01-01 | E5: =F5 -> 46023.265 | F5: =G3 -> 46023.265 | G5: =F5 + RANDBETWEEN(5, 120) / 86400 -> 46023.266 | H5: =INT((G5 - F5) * 86400/60) + MOD(INT((G5 - F5) * 86400),60)/100 -> 1.24 | I5: COMPLETED | J5: 0 | K5: Success
A6: jbex_0005 | B6: ctx_0025 | C6: =_xlfn.XLOOKUP(B6, Mapping!A:A, Mapping!B:B, "Not Found") -> LOANIQ-PAST-DUE-DATA | D6: 2026-01-01 | E6: =F6 -> 46023.265 | F6: =G4 -> 46023.265 | G6: =F6 + RANDBETWEEN(5, 120) / 86400 -> 46023.265 | H6: =INT((G6 - F6) * 86400/60) + MOD(INT((G6 - F6) * 86400),60)/100 -> 0.57 | I6: COMPLETED | J6: 0 | K6: Success
A7: jbex_0006 | B7: ctx_0026 | C7: =_xlfn.XLOOKUP(B7, Mapping!A:A, Mapping!B:B, "Not Found") -> AR-ML-LS2-TRIGGER | D7: 2026-01-01 | E7: =F7 -> 46023.266 | F7: =IF(G5 > G6, G5, G6) -> 46023.266 | G7: =F7 + RANDBETWEEN(5, 120) / 86400 -> 46023.268 | H7: =INT((G7 - F7) * 86400/60) + MOD(INT((G7 - F7) * 86400),60)/100 -> 1.54 | I7: COMPLETED | J7: 0 | K7: Success
A8: jbex_0007 | B8: ctx_0028 | C8: =_xlfn.XLOOKUP(B8, Mapping!A:A, Mapping!B:B, "Not Found") -> NEW-BB-FUNDING-RATES-DOWNLOAD | D8: 2026-01-02 | E8: =D3 + JobGroupExecutionsOLD!C3 -> 46023.25 | F8: =IF(E3 > ResourceAvailabilityEvents!E3, E3, ResourceAvailabilityEvents!E3) -> 46024.25 | G8: =F8 + RANDBETWEEN(5, 120) / 86400 -> 46024.25 | H8: =INT((G8 - F8) * 86400/60) + MOD(INT((G8 - F8) * 86400),60)/100 -> 0.36 | I8: COMPLETED | J8: 0 | K8: Success
A9: jbex_0008 | B9: ctx_0022 | C9: =_xlfn.XLOOKUP(B9, Mapping!A:A, Mapping!B:B, "Not Found") -> AR-ML-LS2-TRIGGER | D9: 2026-01-02 | E9: =F9 -> 46024.25 | F9: =G8 -> 46024.25 | G9: =F9 + RANDBETWEEN(5, 120) / 86400 -> 46024.251 | H9: =INT((G9 - F9) * 86400/60) + MOD(INT((G9 - F9) * 86400),60)/100 -> 0.46 | I9: COMPLETED | J9: 0 | K9: Success
A10: jbex_0009 | B10: ctx_0023 | C10: =_xlfn.XLOOKUP(B10, Mapping!A:A, Mapping!B:B, "Not Found") -> CODE-DESC | D10: 2026-01-02 | E10: =F10 -> 46024.25 | F10: =G8 -> 46024.25 | G10: =F10 + RANDBETWEEN(5, 120) / 86400 -> 46024.252 | H10: =INT((G10 - F10) * 86400/60) + MOD(INT((G10 - F10) * 86400),60)/100 -> 1.41 | I10: COMPLETED | J10: 0 | K10: Success
A11: jbex_0010 | B11: ctx_0024 | C11: =_xlfn.XLOOKUP(B11, Mapping!A:A, Mapping!B:B, "Not Found") -> ONLINE-TO-HIST-SYNC-EXCEPTIONS | D11: 2026-01-02 | E11: =F11 -> 46024.251 | F11: =G9 -> 46024.251 | G11: =F11 + RANDBETWEEN(5, 120) / 86400 -> 46024.252 | H11: =INT((G11 - F11) * 86400/60) + MOD(INT((G11 - F11) * 86400),60)/100 -> 1.33 | I11: COMPLETED | J11: 0 | K11: Success
A12: jbex_0011 | B12: ctx_0025 | C12: =_xlfn.XLOOKUP(B12, Mapping!A:A, Mapping!B:B, "Not Found") -> LOANIQ-PAST-DUE-DATA | D12: 2026-01-02 | E12: =F12 -> 46024.252 | F12: =G10 -> 46024.252 | G12: =F12 + RANDBETWEEN(5, 120) / 86400 -> 46024.252 | H12: =INT((G12 - F12) * 86400/60) + MOD(INT((G12 - F12) * 86400),60)/100 -> 1.03 | I12: COMPLETED | J12: 0 | K12: Success
A13: jbex_0012 | B13: ctx_0026 | C13: =_xlfn.XLOOKUP(B13, Mapping!A:A, Mapping!B:B, "Not Found") -> AR-ML-LS2-TRIGGER | D13: 2026-01-02 | E13: =F13 -> 46024.252 | F13: =IF(G11 > G12, G11, G12) -> 46024.252 | G13: =F13 + RANDBETWEEN(5, 120) / 86400 -> 46024.253 | H13: =INT((G13 - F13) * 86400/60) + MOD(INT((G13 - F13) * 86400),60)/100 -> 1.21 | I13: COMPLETED | J13: 0 | K13: Success
A14: jbex_0013 | B14: ctx_0028 | C14: =_xlfn.XLOOKUP(B14, Mapping!A:A, Mapping!B:B, "Not Found") -> NEW-BB-FUNDING-RATES-DOWNLOAD | D14: 2026-01-03 | E14: =D4 + JobGroupExecutionsOLD!C4 -> 46023.25 | F14: =IF(E4 > ResourceAvailabilityEvents!E4, E4, ResourceAvailabilityEvents!E4) -> 46025.25 | G14: =F14 + RANDBETWEEN(5, 120) / 86400 -> 46025.25 | H14: =INT((G14 - F14) * 86400/60) + MOD(INT((G14 - F14) * 86400),60)/100 -> 0.23 | I14: COMPLETED | J14: 0 | K14: Success
A15: jbex_0014 | B15: ctx_0022 | C15: =_xlfn.XLOOKUP(B15, Mapping!A:A, Mapping!B:B, "Not Found") -> AR-ML-LS2-TRIGGER | D15: 2026-01-03 | E15: =F15 -> 46025.25 | F15: =G14 -> 46025.25 | G15: =F15 + RANDBETWEEN(5, 120) / 86400 -> 46025.251 | H15: =INT((G15 - F15) * 86400/60) + MOD(INT((G15 - F15) * 86400),60)/100 -> 0.2 | I15: COMPLETED | J15: 0 | K15: Success
A16: jbex_0015 | B16: ctx_0023 | C16: =_xlfn.XLOOKUP(B16, Mapping!A:A, Mapping!B:B, "Not Found") -> CODE-DESC | D16: 2026-01-03 | E16: =F16 -> 46025.25 | F16: =G14 -> 46025.25 | G16: =F16 + RANDBETWEEN(5, 120) / 86400 -> 46025.252 | H16: =INT((G16 - F16) * 86400/60) + MOD(INT((G16 - F16) * 86400),60)/100 -> 1.53 | I16: COMPLETED | J16: 0 | K16: Success
A17: jbex_0016 | B17: ctx_0024 | C17: =_xlfn.XLOOKUP(B17, Mapping!A:A, Mapping!B:B, "Not Found") -> ONLINE-TO-HIST-SYNC-EXCEPTIONS | D17: 2026-01-03 | E17: =F17 -> 46025.251 | F17: =G15 -> 46025.251 | G17: =F17 + RANDBETWEEN(5, 120) / 86400 -> 46025.252 | H17: =INT((G17 - F17) * 86400/60) + MOD(INT((G17 - F17) * 86400),60)/100 -> 1.35 | I17: COMPLETED | J17: 0 | K17: Success
A18: jbex_0017 | B18: ctx_0025 | C18: =_xlfn.XLOOKUP(B18, Mapping!A:A, Mapping!B:B, "Not Found") -> LOANIQ-PAST-DUE-DATA | D18: 2026-01-03 | E18: =F18 -> 46025.252 | F18: =G16 -> 46025.252 | G18: =F18 + RANDBETWEEN(5, 120) / 86400 -> 46025.252 | H18: =INT((G18 - F18) * 86400/60) + MOD(INT((G18 - F18) * 86400),60)/100 -> 1.13 | I18: COMPLETED | J18: 0 | K18: Success
A19: jbex_0018 | B19: ctx_0026 | C19: =_xlfn.XLOOKUP(B19, Mapping!A:A, Mapping!B:B, "Not Found") -> AR-ML-LS2-TRIGGER | D19: 2026-01-03 | E19: =F19 -> 46025.252 | F19: =IF(G17 > G18, G17, G18) -> 46025.252 | G19: =F19 + RANDBETWEEN(5, 120) / 86400 -> 46025.253 | H19: =INT((G19 - F19) * 86400/60) + MOD(INT((G19 - F19) * 86400),60)/100 -> 0.36 | I19: COMPLETED | J19: 0 | K19: Success
A20: jbex_0019 | B20: ctx_0019 | C20: =_xlfn.XLOOKUP(B20, Mapping!A:A, Mapping!B:B, "Not Found") -> NEW-BB-FUNDING-RATES-DOWNLOAD | D20: 2026-01-01 | E20: =D5 + JobGroupExecutionsOLD!C5 -> 46023.583 | F20: =IF(E5 > ResourceAvailabilityEvents!E11, E5, ResourceAvailabilityEvents!E11) -> 46023.583 | G20: =F20 + RANDBETWEEN(280, 400) / 86400 -> 46023.588 | H20: =INT((G20 - F20) * 86400/60) + MOD(INT((G20 - F20) * 86400),60)/100 -> 6.28 | I20: COMPLETED | J20: 0 | K20: Success
A21: jbex_0020 | B21: ctx_0013 | C21: =_xlfn.XLOOKUP(B21, Mapping!A:A, Mapping!B:B, "Not Found") -> AR-ML-LS2-TRIGGER | D21: 2026-01-01 | E21: =F21 -> 46023.588 | F21: =G20 -> 46023.588 | G21: =F21 + RANDBETWEEN(280, 390) / 86400 -> 46023.591 | H21: =INT((G21 - F21) * 86400/60) + MOD(INT((G21 - F21) * 86400),60)/100 -> 4.46 | I21: COMPLETED | J21: 0 | K21: Success
A22: jbex_0021 | B22: ctx_0014 | C22: =_xlfn.XLOOKUP(B22, Mapping!A:A, Mapping!B:B, "Not Found") -> CODE-DESC | D22: 2026-01-01 | E22: =F22 -> 46023.588 | F22: =G20 -> 46023.588 | G22: =F22 + RANDBETWEEN(350, 450) / 86400 -> 46023.592 | H22: =INT((G22 - F22) * 86400/60) + MOD(INT((G22 - F22) * 86400),60)/100 -> 6.31 | I22: COMPLETED | J22: 0 | K22: Success
A23: jbex_0022 | B23: ctx_0015 | C23: =_xlfn.XLOOKUP(B23, Mapping!A:A, Mapping!B:B, "Not Found") -> ONLINE-TO-HIST-SYNC-EXCEPTIONS | D23: 2026-01-01 | E23: =F23 -> 46023.591 | F23: =G21 -> 46023.591 | G23: =F23 + RANDBETWEEN(410, 710) / 86400 -> 46023.597 | H23: =INT((G23 - F23) * 86400/60) + MOD(INT((G23 - F23) * 86400),60)/100 -> 8.1 | I23: COMPLETED | J23: 0 | K23: Success
A24: jbex_0023 | B24: ctx_0016 | C24: =_xlfn.XLOOKUP(B24, Mapping!A:A, Mapping!B:B, "Not Found") -> LOANIQ-PAST-DUE-DATA | D24: 2026-01-01 | E24: =F24 -> 46023.592 | F24: =G22 -> 46023.592 | G24: =F24 + RANDBETWEEN(350, 650) / 86400 -> 46023.598 | H24: =INT((G24 - F24) * 86400/60) + MOD(INT((G24 - F24) * 86400),60)/100 -> 8 | I24: COMPLETED | J24: 0 | K24: Success
A25: jbex_0024 | B25: ctx_0018 | C25: =_xlfn.XLOOKUP(B25, Mapping!A:A, Mapping!B:B, "Not Found") -> APMS-LL-AWS-S3-UPLOAD | D25: 2026-01-01 | E25: =F25 -> 46023.597 | F25: =G23 -> 46023.597 | G25: =F25 + RANDBETWEEN(250, 450) / 86400 -> 46023.602 | H25: =INT((G25 - F25) * 86400/60) + MOD(INT((G25 - F25) * 86400),60)/100 -> 7.17 | I25: COMPLETED | J25: 0 | K25: Success
A26: jbex_0025 | B26: ctx_0017 | C26: =_xlfn.XLOOKUP(B26, Mapping!A:A, Mapping!B:B, "Not Found") -> AR-ML-LS2-TRIGGER | D26: 2026-01-01 | E26: =F26 -> 46023.598 | F26: =G24 -> 46023.598 | G26: =F26 + RANDBETWEEN(250, 450) / 86400 -> 46023.602 | H26: =INT((G26 - F26) * 86400/60) + MOD(INT((G26 - F26) * 86400),60)/100 -> 5.5 | I26: COMPLETED | J26: 0 | K26: Success
A27: jbex_0026 | B27: ctx_0020 | C27: =_xlfn.XLOOKUP(B27, Mapping!A:A, Mapping!B:B, "Not Found") -> NEW-LOANIQ-COLLATERAL-MIG | D27: 2026-01-01 | E27: =F27 -> 46023.602 | F27: =G26 -> 46023.602 | G27: =F27 + RANDBETWEEN(250, 450) / 86400 -> 46023.605 | H27: =INT((G27 - F27) * 86400/60) + MOD(INT((G27 - F27) * 86400),60)/100 -> 4.19 | I27: COMPLETED | J27: 0 | K27: Success
A28: jbex_0027 | B28: ctx_0012 | C28: =_xlfn.XLOOKUP(B28, Mapping!A:A, Mapping!B:B, "Not Found") -> LS2H-DAILY-PREP | D28: 2026-01-01 | E28: =F28 -> 46023.605 | F28: =IF(G25 > G27, G25, G27) -> 46023.605 | G28: =F28 + RANDBETWEEN(150, 350) / 86400 -> 46023.607 | H28: =INT((G28 - F28) * 86400/60) + MOD(INT((G28 - F28) * 86400),60)/100 -> 2.29 | I28: COMPLETED | J28: 0 | K28: Success
A29: jbex_0028 | B29: ctx_0019 | C29: =_xlfn.XLOOKUP(B29, Mapping!A:A, Mapping!B:B, "Not Found") -> NEW-BB-FUNDING-RATES-DOWNLOAD | D29: 2026-01-02 | E29: =D6 + JobGroupExecutionsOLD!C6 -> 46023.583 | F29: =IF(E6 > ResourceAvailabilityEvents!E12, E6, ResourceAvailabilityEvents!E12) -> 46024.583 | G29: =F29 + RANDBETWEEN(280, 400) / 86400 -> 46024.587 | H29: =INT((G29 - F29) * 86400/60) + MOD(INT((G29 - F29) * 86400),60)/100 -> 5.42 | I29: COMPLETED | J29: 0 | K29: Success
A30: jbex_0029 | B30: ctx_0013 | C30: =_xlfn.XLOOKUP(B30, Mapping!A:A, Mapping!B:B, "Not Found") -> AR-ML-LS2-TRIGGER | D30: 2026-01-02 | E30: =F30 -> 46024.587 | F30: =G29 -> 46024.587 | G30: =F30 + RANDBETWEEN(280, 390) / 86400 -> 46024.592 | H30: =INT((G30 - F30) * 86400/60) + MOD(INT((G30 - F30) * 86400),60)/100 -> 6.09 | I30: COMPLETED | J30: 0 | K30: Success
A31: jbex_0030 | B31: ctx_0014 | C31: =_xlfn.XLOOKUP(B31, Mapping!A:A, Mapping!B:B, "Not Found") -> CODE-DESC | D31: 2026-01-02 | E31: =F31 -> 46024.587 | F31: =G29 -> 46024.587 | G31: =F31 + RANDBETWEEN(350, 450) / 86400 -> 46024.592 | H31: =INT((G31 - F31) * 86400/60) + MOD(INT((G31 - F31) * 86400),60)/100 -> 6.55 | I31: COMPLETED | J31: 0 | K31: Success
A32: jbex_0031 | B32: ctx_0015 | C32: =_xlfn.XLOOKUP(B32, Mapping!A:A, Mapping!B:B, "Not Found") -> ONLINE-TO-HIST-SYNC-EXCEPTIONS | D32: 2026-01-02 | E32: =F32 -> 46024.592 | F32: =G30 -> 46024.592 | G32: =F32 + RANDBETWEEN(410, 710) / 86400 -> 46024.598 | H32: =INT((G32 - F32) * 86400/60) + MOD(INT((G32 - F32) * 86400),60)/100 -> 9.44 | I32: COMPLETED | J32: 0 | K32: Success
A33: jbex_0032 | B33: ctx_0016 | C33: =_xlfn.XLOOKUP(B33, Mapping!A:A, Mapping!B:B, "Not Found") -> LOANIQ-PAST-DUE-DATA | D33: 2026-01-02 | E33: =F33 -> 46024.592 | F33: =G31 -> 46024.592 | G33: =F33 + RANDBETWEEN(350, 650) / 86400 -> 46024.598 | H33: =INT((G33 - F33) * 86400/60) + MOD(INT((G33 - F33) * 86400),60)/100 -> 9.1 | I33: COMPLETED | J33: 0 | K33: Success
A34: jbex_0033 | B34: ctx_0018 | C34: =_xlfn.XLOOKUP(B34, Mapping!A:A, Mapping!B:B, "Not Found") -> APMS-LL-AWS-S3-UPLOAD | D34: 2026-01-02 | E34: =F34 -> 46024.598 | F34: =G32 -> 46024.598 | G34: =F34 + RANDBETWEEN(250, 450) / 86400 -> 46024.602 | H34: =INT((G34 - F34) * 86400/60) + MOD(INT((G34 - F34) * 86400),60)/100 -> 5.43 | I34: COMPLETED | J34: 0 | K34: Success
A35: jbex_0034 | B35: ctx_0017 | C35: =_xlfn.XLOOKUP(B35, Mapping!A:A, Mapping!B:B, "Not Found") -> AR-ML-LS2-TRIGGER | D35: 2026-01-02 | E35: =F35 -> 46024.598 | F35: =G33 -> 46024.598 | G35: =F35 + RANDBETWEEN(250, 450) / 86400 -> 46024.602 | H35: =INT((G35 - F35) * 86400/60) + MOD(INT((G35 - F35) * 86400),60)/100 -> 4.38 | I35: COMPLETED | J35: 0 | K35: Success
A36: jbex_0035 | B36: ctx_0020 | C36: =_xlfn.XLOOKUP(B36, Mapping!A:A, Mapping!B:B, "Not Found") -> NEW-LOANIQ-COLLATERAL-MIG | D36: 2026-01-02 | E36: =F36 -> 46024.602 | F36: =G35 -> 46024.602 | G36: =F36 + RANDBETWEEN(250, 450) / 86400 -> 46024.605 | H36: =INT((G36 - F36) * 86400/60) + MOD(INT((G36 - F36) * 86400),60)/100 -> 4.59 | I36: COMPLETED | J36: 0 | K36: Success
A37: jbex_0036 | B37: ctx_0012 | C37: =_xlfn.XLOOKUP(B37, Mapping!A:A, Mapping!B:B, "Not Found") -> LS2H-DAILY-PREP | D37: 2026-01-02 | E37: =F37 -> 46024.605 | F37: =IF(G34 > G36, G34, G36) -> 46024.605 | G37: =F37 + RANDBETWEEN(150, 350) / 86400 -> 46024.609 | H37: =INT((G37 - F37) * 86400/60) + MOD(INT((G37 - F37) * 86400),60)/100 -> 5.37 | I37: COMPLETED | J37: 0 | K37: Success
A38: jbex_0037 | B38: ctx_0019 | C38: =_xlfn.XLOOKUP(B38, Mapping!A:A, Mapping!B:B, "Not Found") -> NEW-BB-FUNDING-RATES-DOWNLOAD | D38: 2026-01-03 | E38: =D7 + JobGroupExecutionsOLD!C7 -> 46023.583 | F38: =IF(E7 > ResourceAvailabilityEvents!E13, E7, ResourceAvailabilityEvents!E13) -> 46025.583 | G38: =F38 + RANDBETWEEN(280, 400) / 86400 -> 46025.588 | H38: =INT((G38 - F38) * 86400/60) + MOD(INT((G38 - F38) * 86400),60)/100 -> 6.22 | I38: COMPLETED | J38: 0 | K38: Success
A39: jbex_0038 | B39: ctx_0013 | C39: =_xlfn.XLOOKUP(B39, Mapping!A:A, Mapping!B:B, "Not Found") -> AR-ML-LS2-TRIGGER | D39: 2026-01-03 | E39: =F39 -> 46025.588 | F39: =G38 -> 46025.588 | G39: =F39 + RANDBETWEEN(280, 390) / 86400 -> 46025.592 | H39: =INT((G39 - F39) * 86400/60) + MOD(INT((G39 - F39) * 86400),60)/100 -> 5.48 | I39: COMPLETED | J39: 0 | K39: Success
A40: jbex_0039 | B40: ctx_0014 | C40: =_xlfn.XLOOKUP(B40, Mapping!A:A, Mapping!B:B, "Not Found") -> CODE-DESC | D40: 2026-01-03 | E40: =F40 -> 46025.588 | F40: =G38 -> 46025.588 | G40: =F40 + RANDBETWEEN(350, 450) / 86400 -> 46025.593 | H40: =INT((G40 - F40) * 86400/60) + MOD(INT((G40 - F40) * 86400),60)/100 -> 7.08 | I40: COMPLETED | J40: 0 | K40: Success
...

Sheet Mapping
A1: jobContextId | B1: JobName
A2: ctx_0002 | B2: LS2H-DAILY-PREP
A3: ctx_0003 | B3: AR-ML-LS2-TRIGGER
A4: ctx_0004 | B4: CODE-DESC
A5: ctx_0005 | B5: ONLINE-TO-HIST-SYNC-EXCEPTIONS
A6: ctx_0006 | B6: LOANIQ-PAST-DUE-DATA
A7: ctx_0007 | B7: AR-ML-LS2-TRIGGER
A8: ctx_0008 | B8: APMS-LL-AWS-S3-UPLOAD
A9: ctx_0010 | B9: NEW-BB-FUNDING-RATES-DOWNLOAD
A10: ctx_0011 | B10: NEW-LOANIQ-COLLATERAL-MIG
A11: ctx_0012 | B11: LS2H-DAILY-PREP
A12: ctx_0013 | B12: AR-ML-LS2-TRIGGER
... A29: ctx_0032 | B29: reportGenerationJob

Sheet ResourceAvailabilityEvents
A1: id | B1: resourceId | C1: businessDate | D1: availabilityTime | E1: availabilityDateTime
A2: RSD_file1_20260101 | B2: RES_005 | C2: 2026-01-01 | D2: =(JobGroupExecutionsOLD!C2) + TIME(0,20,0) -> 0.26388889 | E2: =C2+D2 -> 46023.264
A3: RSD_file1_20250102 | B3: RES_005 | C3: 2026-01-02 | D3: =(JobGroupExecutionsOLD!C3) -> 0.25 | E3: =C3+D3 -> 46024.25
A4: RSD_file1_20250103 | B4: RES_005 | C4: 2026-01-03 | D4: =(JobGroupExecutionsOLD!C4) -> 0.25 | E4: =C4+D4 -> 46025.25
A5: RSD_file2_20250101 | B5: RES_002 | C5: 2026-01-01 | D5: =(JobGroupExecutionsOLD!C8) -> 0.875 | E5: =C5+D5 -> 46023.875
A6: RSD_file2_20250102 | B6: RES_002 | C6: 2026-01-02 | D6: =(JobGroupExecutionsOLD!C9) -> 0.875 | E6: =C6+D6 -> 46024.875
A7: RSD_file2_20250103 | B7: RES_002 | C7: 2026-01-03 | D7: =(JobGroupExecutionsOLD!C10) -> 0.875 | E7: =C7+D7 -> 46025.875
A8: RSD_file3_20260101 | B8: RES_004 | C8: 2026-01-01 | D8: =(JobGroupExecutionsOLD!C8) -> 0.875 | E8: =C8+D8 -> 46023.875
A9: RSD_file3_20260102 | B9: RES_004 | C9: 2026-01-02 | D9: =(JobGroupExecutionsOLD!C9) -> 0.875 | E9: =C9+D9 -> 46024.875
A10: RSD_file3_20260103 | B10: RES_004 | C10: 2026-01-03 | D10: =(JobGroupExecutionsOLD!C10) -> 0.875 | E10: =C10+D10 -> 46025.875
A11: RSD_file4_20260101 | B11: RES_006 | C11: 2026-01-01 | D11: =(JobGroupExecutionsOLD!C5) -> 0.58333333 | E11: =C11+D11 -> 46023.583
A12: RSD_file4_20260102 | B12: RES_006 | C12: 2026-01-02 | D12: =(JobGroupExecutionsOLD!C6) -> 0.58333333 | E12: =C12+D12 -> 46024.583
A13: RSD_file4_20260103 | B13: RES_006 | C13: 2026-01-03 | D13: =(JobGroupExecutionsOLD!C7) -> 0.58333333 | E13: =C13+D13 -> 46025.583
A14: RSD_file5_20260101 | B14: RES_001 | C14: 2026-01-01 | D14: =(JobGroupExecutionsOLD!C8) -> 0.875 | E14: =C14+D14 -> 46023.875
A15: RSD_file5_20260102 | B15: RES_001 | C15: 2026-01-02 | D15: =(JobGroupExecutionsOLD!C9) -> 0.875 | E15: =C15+D15 -> 46024.875
A16: RSD_file5_20260103 | B16: RES_001 | C16: 2026-01-03 | D16: =(JobGroupExecutionsOLD!C10) -> 0.875 | E16: =C16+D16 -> 46025.875
A17: RSD_file6_20260101 | B17: RES_003 | C17: 2026-01-01 | D17: =(JobGroupExecutionsOLD!C8) + TIME(0,35,0) -> 0.89930556 | E17: =C17+D17 -> 46023.899
A18: RSD_file6_20260102 | B18: RES_003 | C18: 2026-01-02 | D18: =(JobGroupExecutionsOLD!C9) -> 0.875 | E18: =C18+D18 -> 46024.875
A19: RSD_file6_20260103 | B19: RES_003 | C19: 2026-01-03 | D19: =(JobGroupExecutionsOLD!C10) + TIME(1,5,0) -> 0.92013889 | E19: =C19+D19 -> 46025.92
